C:\Users\Aideen\OneDrive\Documents\CT4101 - Machine Learning\Assignment 2\CT4041-assignment-2>C:/Users/Aideen/AppData/Local/Programs/Python/Python38/python.exe "c:/Users/Aideen/OneDrive/Documents/CT4101 - Machine Learning/Assignment 2/CT4041-assignment-2/implementation_from_scratch.py"
Traceback (most recent call last):
  File "C:\Users\Aideen\AppData\Local\Programs\Python\Python38\lib\site-packages\pandas\core\indexes\base.py", line 2895, in get_loc
    return self._engine.get_loc(casted_key)
  File "pandas\_libs\index.pyx", line 70, in pandas._libs.index.IndexEngine.get_loc      
  File "pandas\_libs\index.pyx", line 101, in pandas._libs.index.IndexEngine.get_loc     
  File "pandas\_libs\hashtable_class_helper.pxi", line 1675, in pandas._libs.hashtable.PyObjectHashTable.get_item
  File "pandas\_libs\hashtable_class_helper.pxi", line 1683, in pandas._libs.hashtable.PyObjectHashTable.get_item
KeyError: 0

The above exception was the direct cause of the following exception:

Traceback (most recent call last):
  File "c:/Users/Aideen/OneDrive/Documents/CT4101 - Machine Learning/Assignment 2/CT4041-assignment-2/implementation_from_scratch.py", line 197, in <module>
    main()
  File "c:/Users/Aideen/OneDrive/Documents/CT4101 - Machine Learning/Assignment 2/CT4041-assignment-2/implementation_from_scratch.py", line 26, in main
    root_node = build_tree(train, attributes)
  File "c:/Users/Aideen/OneDrive/Documents/CT4101 - Machine Learning/Assignment 2/CT4041-assignment-2/implementation_from_scratch.py", line 37, in build_tree
    data_class_checked = data_class_check(data)
  File "c:/Users/Aideen/OneDrive/Documents/CT4101 - Machine Learning/Assignment 2/CT4041-assignment-2/implementation_from_scratch.py", line 153, in data_class_check
    if row[-1] != data[0][-1]:
  File "C:\Users\Aideen\AppData\Local\Programs\Python\Python38\lib\site-packages\pandas\core\frame.py", line 2902, in __getitem__
    indexer = self.columns.get_loc(key)
  File "C:\Users\Aideen\AppData\Local\Programs\Python\Python38\lib\site-packages\pandas\core\indexes\base.py", line 2897, in get_loc
    raise KeyError(key) from err
KeyError: 0
